C:\Users\Bob\Desktop\modme>python Tornado.py
server Started
Django version 1.11.24, using settings 'multiTask.settings'
Tornado 4.3 server started at http://127.0.0.1:9000/
Quit the server with CONTROL-C
Internal Server Error: /
Traceback (most recent call last):
  File "C:\Users\Bob\AppData\Local\Programs\Python\Python37\lib\site-packages\django\core\handlers\exception.py", line 41, in inner
    response = get_response(request)
  File "C:\Users\Bob\AppData\Local\Programs\Python\Python37\lib\site-packages\django\core\handlers\base.py", line 249, in _legacy_get_response
    response = self._get_response(request)
  File "C:\Users\Bob\AppData\Local\Programs\Python\Python37\lib\site-packages\django\core\handlers\base.py", line 172, in _get_response
    resolver_match = resolver.resolve(request.path_info)
  File "C:\Users\Bob\AppData\Local\Programs\Python\Python37\lib\site-packages\django\urls\resolvers.py", line 364, in resolve
    for pattern in self.url_patterns:
  File "C:\Users\Bob\AppData\Local\Programs\Python\Python37\lib\site-packages\django\utils\functional.py", line 35, in __get__
    res = instance.__dict__[self.name] = self.func(instance)
  File "C:\Users\Bob\AppData\Local\Programs\Python\Python37\lib\site-packages\django\urls\resolvers.py", line 407, in url_patterns
    patterns = getattr(self.urlconf_module, "urlpatterns", self.urlconf_module)
  File "C:\Users\Bob\AppData\Local\Programs\Python\Python37\lib\site-packages\django\utils\functional.py", line 35, in __get__
    res = instance.__dict__[self.name] = self.func(instance)
  File "C:\Users\Bob\AppData\Local\Programs\Python\Python37\lib\site-packages\django\urls\resolvers.py", line 400, in urlconf_module
    return import_module(self.urlconf_name)
  File "C:\Users\Bob\AppData\Local\Programs\Python\Python37\lib\importlib\__init__.py", line 127, in import_module
    return _bootstrap._gcd_import(name[level:], package, level)
  File "<frozen importlib._bootstrap>", line 1006, in _gcd_import
  File "<frozen importlib._bootstrap>", line 983, in _find_and_load
  File "<frozen importlib._bootstrap>", line 967, in _find_and_load_unlocked
  File "<frozen importlib._bootstrap>", line 677, in _load_unlocked
  File "<frozen importlib._bootstrap_external>", line 728, in exec_module
  File "<frozen importlib._bootstrap>", line 219, in _call_with_frames_removed
  File "C:\Users\Bob\Desktop\modme\multiTask\urls.py", line 22, in <module>
    url(r'^ModME/', include('ModME.urls', namespace="ModME")),
  File "C:\Users\Bob\AppData\Local\Programs\Python\Python37\lib\site-packages\django\conf\urls\__init__.py", line 50, in include
    urlconf_module = import_module(urlconf_module)
  File "C:\Users\Bob\AppData\Local\Programs\Python\Python37\lib\importlib\__init__.py", line 127, in import_module
    return _bootstrap._gcd_import(name[level:], package, level)
  File "<frozen importlib._bootstrap>", line 1006, in _gcd_import
  File "<frozen importlib._bootstrap>", line 983, in _find_and_load
  File "<frozen importlib._bootstrap>", line 967, in _find_and_load_unlocked
  File "<frozen importlib._bootstrap>", line 677, in _load_unlocked
  File "<frozen importlib._bootstrap_external>", line 728, in exec_module
  File "<frozen importlib._bootstrap>", line 219, in _call_with_frames_removed
  File "C:\Users\Bob\Desktop\modme\ModME\urls.py", line 3, in <module>
    from ModME import views
  File "C:\Users\Bob\Desktop\modme\ModME\views.py", line 286
    try:
       ^
TabError: inconsistent use of tabs and spaces in indentation
ERROR:django.request:Internal Server Error: /
Traceback (most recent call last):
  File "C:\Users\Bob\AppData\Local\Programs\Python\Python37\lib\site-packages\django\core\handlers\exception.py", line 41, in inner
    response = get_response(request)
  File "C:\Users\Bob\AppData\Local\Programs\Python\Python37\lib\site-packages\django\core\handlers\base.py", line 249, in _legacy_get_response
    response = self._get_response(request)
  File "C:\Users\Bob\AppData\Local\Programs\Python\Python37\lib\site-packages\django\core\handlers\base.py", line 172, in _get_response
    resolver_match = resolver.resolve(request.path_info)
  File "C:\Users\Bob\AppData\Local\Programs\Python\Python37\lib\site-packages\django\urls\resolvers.py", line 364, in resolve
    for pattern in self.url_patterns:
  File "C:\Users\Bob\AppData\Local\Programs\Python\Python37\lib\site-packages\django\utils\functional.py", line 35, in __get__
    res = instance.__dict__[self.name] = self.func(instance)
  File "C:\Users\Bob\AppData\Local\Programs\Python\Python37\lib\site-packages\django\urls\resolvers.py", line 407, in url_patterns
    patterns = getattr(self.urlconf_module, "urlpatterns", self.urlconf_module)
  File "C:\Users\Bob\AppData\Local\Programs\Python\Python37\lib\site-packages\django\utils\functional.py", line 35, in __get__
    res = instance.__dict__[self.name] = self.func(instance)
  File "C:\Users\Bob\AppData\Local\Programs\Python\Python37\lib\site-packages\django\urls\resolvers.py", line 400, in urlconf_module
    return import_module(self.urlconf_name)
  File "C:\Users\Bob\AppData\Local\Programs\Python\Python37\lib\importlib\__init__.py", line 127, in import_module
    return _bootstrap._gcd_import(name[level:], package, level)
  File "<frozen importlib._bootstrap>", line 1006, in _gcd_import
  File "<frozen importlib._bootstrap>", line 983, in _find_and_load
  File "<frozen importlib._bootstrap>", line 967, in _find_and_load_unlocked
  File "<frozen importlib._bootstrap>", line 677, in _load_unlocked
  File "<frozen importlib._bootstrap_external>", line 728, in exec_module
  File "<frozen importlib._bootstrap>", line 219, in _call_with_frames_removed
  File "C:\Users\Bob\Desktop\modme\multiTask\urls.py", line 22, in <module>
    url(r'^ModME/', include('ModME.urls', namespace="ModME")),
  File "C:\Users\Bob\AppData\Local\Programs\Python\Python37\lib\site-packages\django\conf\urls\__init__.py", line 50, in include
    urlconf_module = import_module(urlconf_module)
  File "C:\Users\Bob\AppData\Local\Programs\Python\Python37\lib\importlib\__init__.py", line 127, in import_module
    return _bootstrap._gcd_import(name[level:], package, level)
  File "<frozen importlib._bootstrap>", line 1006, in _gcd_import
  File "<frozen importlib._bootstrap>", line 983, in _find_and_load
  File "<frozen importlib._bootstrap>", line 967, in _find_and_load_unlocked
  File "<frozen importlib._bootstrap>", line 677, in _load_unlocked
  File "<frozen importlib._bootstrap_external>", line 728, in exec_module
  File "<frozen importlib._bootstrap>", line 219, in _call_with_frames_removed
  File "C:\Users\Bob\Desktop\modme\ModME\urls.py", line 3, in <module>
    from ModME import views
  File "C:\Users\Bob\Desktop\modme\ModME\views.py", line 286
    try:
       ^
TabError: inconsistent use of tabs and spaces in indentation
ERROR:tornado.access:500 GET / (::1) 78.08ms

============================================================================================================================================================================================